<?xml version="1.0" ?>
<!-- =================================================================================== -->
<!-- |    This document was autogenerated by xacro from winter.urdf.xacro              | -->
<!-- |    EDITING THIS FILE BY HAND IS NOT RECOMMENDED                                 | -->
<!-- =================================================================================== -->
<robot name="winter" xmlns:xacro="http://www.ros.org/wiki/xacro">
  <!-- gazebo -->
  <!--xacro:include filename="$(find winter_description)/urdf/winter.gazebo"/-->
  <!--base_link-->
  <link name="base_link">
    <visual>
      <geometry>
        <cylinder length="0.127" radius="0.25"/>
      </geometry>
      <origin xyz="0 0 0.1385"/>
    </visual>
    <collision>
      <geometry>
        <cylinder length="0.127" radius="0.25"/>
      </geometry>
      <origin xyz="0 0 0.1385"/>
    </collision>
  </link>
  <!--laser_link-->
  <link name="laser_link">
    <visual>
      <geometry>
        <cylinder length="0.08" radius="0.05"/>
      </geometry>
      <material name="green">
        <color rgba="0 0.8 0 1"/>
      </material>
      <origin xyz="0 0 0.04"/>
    </visual>
    <collision>
      <geometry>
        <cylinder length="0.08" radius="0.05"/>
      </geometry>
      <origin xyz="0 0 0.04"/>
    </collision>
  </link>
  <joint name="laser_link_to_base_link" type="fixed">
    <parent link="base_link"/>
    <child link="laser_link"/>
    <origin xyz="0 0 0.202"/>
  </joint>
  <!-- left wheel-->
  <link name="left_wheel">
    <visual>
      <geometry>
        <cylinder length="0.06" radius="0.075"/>
      </geometry>
      <material name="blue">
        <color rgba="0 0 .8 1"/>
      </material>
      <origin rpy="1.57075 0 0" xyz="0 0 0"/>
    </visual>
  </link>
  <joint name="left_wheel_to_base_link" type="continuous">
    <parent link="base_link"/>
    <child link="left_wheel"/>
    <origin xyz="0.0 0.25 0.075"/>
    <axis xyz="0 1 0"/>
  </joint>
  <!-- right wheel-->
  <link name="right_wheel">
    <visual>
      <geometry>
        <cylinder length="0.06" radius="0.075"/>
      </geometry>
      <material name="blue">
        <color rgba="0 0 .8 1"/>
      </material>
      <origin rpy="1.57075 0 0" xyz="0 0 0"/>
    </visual>
  </link>
  <joint name="right_wheel_to_base_link" type="fixed">
    <parent link="base_link"/>
    <child link="right_wheel"/>
    <origin xyz="0.0 -0.25 0.075"/>
    <axis xyz="0 1 0"/>
  </joint>
</robot>

