<?xml version="1.0"?>
<robot xmlns:xacro="http://www.ros.org/wiki/xacro" name="winter">
	
        <!-- gazebo -->
        <!--xacro:include filename="$(find winter_description)/urdf/winter.gazebo"/-->
        <xacro:property name="body_radius"      value=".25"/>
        <xacro:property name="body_height"      value=".127"/>
	<xacro:property name="body_mass"   	value="0.7" /> 

        <xacro:property name="wheel_separation" value="${body_radius*2}"/>
        <xacro:property name="wheel_radius"     value=".075"/>
        <xacro:property name="wheel_length"     value=".06"/>
        <xacro:property name="wheel_color"      value="0 0 .8 1"/>
	<xacro:property name="wheel_mass"   	value="0.4" /> 

        <xacro:property name="laser_height"     value=".08"/>
        <xacro:property name="laser_radius"     value=".05"/>
	<xacro:property name="laser_mass"   	value="0.2" />

  <!-- Macro for inertia matrix -->
  <xacro:macro name="sphere_inertial_matrix" params="m r">
      <inertial>
          <mass value="${m}" />
          <inertia ixx="${2*m*r*r/5}" ixy="0" ixz="0"
              iyy="${2*m*r*r/5}" iyz="0" 
              izz="${2*m*r*r/5}" />
      </inertial>
  </xacro:macro>

  <xacro:macro name="cylinder_inertial_matrix" params="m r h">
      <inertial>
          <mass value="${m}" />
          <inertia ixx="${m*(3*r*r+h*h)/12}" ixy = "0" ixz = "0"
              iyy="${m*(3*r*r+h*h)/12}" iyz = "0"
              izz="${m*r*r/2}" /> 
      </inertial>
  </xacro:macro>

  <xacro:macro name="box_inertial_matrix" params="m w h d">
      <inertial>
          <mass value="${m}" />
          <inertia ixx="${m*(h*h+d*d)/12}" ixy = "0" ixz = "0"
              iyy="${m*(w*w+d*d)/12}" iyz = "0"
              izz="${m*(w*w+h*h)/12}" /> 
      </inertial>
  </xacro:macro>

<!--base_link-->
        <link name="base_link">
	<cylinder_inertial_matrix  m="${body_mass}" r="${body_radius}" d="${body_length}" />
                <visual>
                        <geometry>
                                <cylinder length="${body_height}" radius="${body_radius}"/>
                        </geometry>
                        <origin xyz="0 0 ${body_height/2+wheel_radius}"/>
                </visual>
                <collision>
                        <geometry>
                                <cylinder length="${body_height}" radius="${body_radius}"/>
                        </geometry>
                        <origin xyz="0 0 ${body_height/2+wheel_radius}"/>
                </collision>
        </link>
	<gazebo reference="base_link">
      		<material>Gazebo/White</material>
  	</gazebo>
<!--laser_link-->
        <link name="laser_link">
	<cylinder_inertial_matrix  m="${laser_mass}" r="${laser_radius}" d="${laser_length}" />
                <visual>
                        <geometry>
                                <cylinder length="${laser_height}" radius="${laser_radius}"/>
                        </geometry>
                        <material name="green">
                                <color rgba="0 0.8 0 1"/>
                        </material>
                        <origin xyz="0 0 ${laser_height/2}"/>
                </visual>
                <collision>
                        <geometry>
                                <cylinder length="${laser_height}" radius="${laser_radius}"/>
                        </geometry>
                        <origin xyz="0 0 ${laser_height/2}"/>
                </collision>
        </link>
  <gazebo reference="laser_link">
      <material>Gazebo/Black</material>
  </gazebo>
        <joint name="laser_link_to_base_link" type="fixed">
            <parent link="base_link"/>
            <child link="laser_link"/>
            <origin xyz="0 0 ${body_height+wheel_radius}"/>
        </joint>

<!-- left wheel-->
        <link name="left_wheel">
                <visual>
                        <geometry>
                                <cylinder length="${wheel_length}" radius="${wheel_radius}"/>
                        </geometry>
                        <material name="blue">
                                <color rgba="${wheel_color}"/>
                        </material>
                        <origin rpy="1.57075 0 0" xyz="0 0 0"/>
                </visual>
        </link>
      <gazebo reference="left_wheel">
          <material>Gazebo/Black</material>
      </gazebo>
        <joint name="left_wheel_to_base_link" type="continuous">
                <parent link="base_link"/>
                <child link="left_wheel"/>
                <origin xyz="0.0 ${wheel_separation/2} ${wheel_radius}"/>
                <axis xyz="0 1 0"/>
        </joint>
<!-- right wheel-->
        <link name="right_wheel">
                <visual>
                        <geometry>
                                <cylinder length="${wheel_length}" radius="${wheel_radius}"/>
                        </geometry>
                        <material name="blue">
                                <color rgba="${wheel_color}"/>
                        </material>
                        <origin rpy="1.57075 0 0" xyz="0 0 0"/>
                </visual>
        </link>
      <gazebo reference="right_wheel">
          <material>Gazebo/Black</material>
      </gazebo>
        <joint name="right_wheel_to_base_link" type="continuous">
                <parent link="base_link"/>
                <child link="right_wheel"/>
                <origin xyz="0.0 -${wheel_separation/2} ${wheel_radius}"/>
                <axis xyz="0 1 0"/>
        </joint>

</robot>
